Workbook

Sheet Evidence Tracker
A1: FCRM Risk Assessment FY2025 — Evidence Tracker
A2: Maps each process step to required evidence, owner, location, and status | System of Record: SharePoint + Jira | Last Updated: April 2026
A4: Process | B4: Sub-Process / Step | C4: Step # | D4: Owner | E4: Expected Evidence / Artifact | F4: Artifact Name / File | G4: SharePoint / Jira Location | H4: Status | I4: Jira Ticket(s) | J4: Last Verified | K4: Verified By | L4: Gap / Notes | M4: Priority | N4: Due Date | O4: Linked SOP | P4: Audit Ready?
A5: Delivery Process | B5: Intake Request | C5: 0 | D5: Amandeep | E5: Jira ticket created, CDE list, initial review record | H5: Missing | O5: 01 - Delivery Process SOP v1.2 | P5: No
B6: Scope / Requirement Def. | C6: 1 | D6: Amandeep | E6: Scope & Requirements Document, SOW reference | H6: Missing | O6: 01 - Delivery Process SOP v1.2 | P6: No
B7: Data Acquisition | C7: 2 | D7: Amandeep | E7: Extraction scripts, extracted dataset files in CA AZ | H7: Missing | O7: 01 - Delivery Process SOP v1.2 | P7: No
B8: Logic Development (Build) | C8: 3 | D8: Karthik | E8: Python-SQL queries in Git, Jira ticket in BUILD IN PROGRESS | H8: Missing | O8: 01 - Delivery Process SOP v1.2 | P8: No
B9: Technical Specifications | C9: 4 | D9: Karthik | E9: Tech spec doc, transformation logic, field-level mapping | H9: Missing | O9: 01 - Delivery Process SOP v1.2 | P9: No
B10: Output Validation | C10: 5 | D10: Karthik | E10: Output validation report, reconciliation results | H10: Missing | O10: 01 - Delivery Process SOP v1.2 | P10: No
B11: Approval | C11: 6 | D11: Karthik | E11: Jira ticket in PO CONCURRENCE → PO APPROVED state | H11: Missing | O11: 01 - Delivery Process SOP v1.2 | P11: No
B12: Deployment | C12: 7 | D12: Karthik | E12: Deployment log, release record | H12: Missing | O12: 01 - Delivery Process SOP v1.2 | P12: No
B13: Delivery / Document | C13: 8 | D13: Karthik | E13: Final output files, delivery confirmation | H13: Missing | O13: 01 - Delivery Process SOP v1.2 | P13: No
A14: Validation & QA | B14: Validation Planning | C14: 1 | D14: Priyanshi | E14: Validation Plan Document, Risk Assessment Matrix | H14: Missing | O14: 02 - QA & Governance SOP v2.1 | P14: No
B15: Data Quality Checks | C15: 2 | D15: Priyanshi | E15: DQ check results (completeness, accuracy, consistency, uniqueness, timeliness) | H15: Missing | O15: 02 - QA & Governance SOP v2.1 | P15: No
B16: Reconciliation | C16: 3 | D16: Priyanshi | E16: Reconciliation report, variance analysis log | H16: Missing | O16: 02 - QA & Governance SOP v2.1 | P16: No
B17: Reasonability Analysis | C17: 4 | D17: Priyanshi | E17: Trend analysis output, outlier detection log, threshold validation | H17: Missing | O17: 02 - QA & Governance SOP v2.1 | P17: No
B18: Peer Review | C18: 5 | D18: Sujai | E18: Peer review sign-off, review comments log | H18: Missing | O18: 02 - QA & Governance SOP v2.1 | P18: No
B19: Output Verification | C19: 6 | D19: Sujai | E19: Output verification report, format compliance log | H19: Missing | O19: 02 - QA & Governance SOP v2.1 | P19: No
B20: Issue Logging | C20: 7 | D20: Sujai | E20: RAID log entry, Jira BLOCKED ticket with issue detail | H20: Missing | O20: 02 - QA & Governance SOP v2.1 | P20: No
B21: Sign-Off & Approval | C21: 8 | D21: Sujai | E21: Signed approval record (AVP+), final validation report | H21: Missing | O21: 02 - QA & Governance SOP v2.1 | P21: No
A22: Data Sourcing & Lineage | B22: Source Identification | C22: 1 | D22: Hua | E22: Master_Data_source_FY2025.xlsx, source identification log | H22: Missing | O22: 03 - Data Sourcing & Lineage v1.0 | P22: No
B23: Access Enablement | C23: 2 | D23: Hua | E23: PIA approval records, access request forms, access approval log | H23: Missing | O23: 03 - Data Sourcing & Lineage v1.0 | P23: No
B24: Data Extraction | C24: 3 | D24: Hua | E24: Extracted dataset files (.csv/.parquet), extraction scripts, extraction validation report | H24: Missing | O24: 03 - Data Sourcing & Lineage v1.0 | P24: No
B25: Data Understanding | C25: 4 | D25: Subham | E25: Data profiling reports, data dictionary / metadata documentation | H25: Missing | O25: 03 - Data Sourcing & Lineage v1.0 | P25: No
B26: Lineage Documentation | C26: 5 | D26: Subham | E26: Data lineage diagrams, transformation logic documentation, lineage register | H26: Missing | O26: 03 - Data Sourcing & Lineage v1.0 | P26: No
B27: Refresh Management | C27: 6 | D27: Raghul | E27: Refresh activity log, refresh validation reports | H27: Missing | O27: 03 - Data Sourcing & Lineage v1.0 | P27: No
B28: Data Retention | C28: 7 | D28: Raghul | E28: Data retention statement, retention policy reference | H28: Missing | O28: 03 - Data Sourcing & Lineage v1.0 | P28: No
A29: Governance & Issue Mgmt | B29: Decision Logging | C29: 1 | D29: Patty | E29: Jira ticket in BUSINESS LOGIC DESIGN DEF state with decision notes | H29: Missing | O29: 04 - Governance SOP | P29: No
B30: Assumption Tracking | C30: 2 | D30: Patty | E30: Jira ticket in METRIC DEFINITION CLARIFICATION state, assumption log | H30: Missing | O30: 04 - Governance SOP | P30: No
B31: Issue Logging | C31: 3 | D31: Patty | E31: RAID log entry, Jira BLOCKED ticket | H31: Missing | O31: 04 - Governance SOP | P31: No
B32: Severity Assessment | C32: 4 | D32: Patty | E32: Severity classification (P1/P2) in RAID log | H32: Missing | O32: 04 - Governance SOP | P32: No
B33: Escalation Pathways | C33: 5 | D33: Tom | E33: Escalation record, Jira comments showing escalation chain | H33: Missing | O33: 04 - Governance SOP | P33: No
B34: Resolution & Unblocking | C34: 6 | D34: Tom | E34: RAID log closure, Jira state transition off BLOCKED | H34: Missing | O34: 04 - Governance SOP | P34: No
B35: Risk Acceptance | C35: 7 | D35: Tom | E35: Risk acceptance record, metric transitioned to NOT AVAILABLE | H35: Missing | O35: 04 - Governance SOP | P35: No
B36: Decommissioning | C36: 8 | D36: Tom | E36: Jira state: NO LONGER REQUIRED or NOT APPLICABLE | H36: Missing | O36: 04 - Governance SOP | P36: No
A37: Access Control & Security | B37: PIA Initiation | C37: 1 | D37: Hua | E37: PIA initiated for each data source requiring personal/sensitive data | H37: Missing | O37: 05 - Access Control SOP | P37: No
B38: Access Request | C38: 2 | D38: Hua | E38: Access request forms submitted per system | H38: Missing | O38: 05 - Access Control SOP | P38: No
B39: Access Approval | C39: 3 | D39: Hua | E39: Access approval records, confirmation emails | H39: Missing | O39: 05 - Access Control SOP | P39: No
B40: DEV vs PROD Separation | C40: 4 | D40: TBD | E40: Evidence of environment separation, access matrix | H40: Missing | O40: 05 - Access Control SOP | P40: No
B41: Periodic Review | C41: 5 | D41: TBD | E41: Periodic access review log, attestation records | H41: Missing | O41: 05 - Access Control SOP | P41: No
...

Sheet Summary Dashboard
A1: Evidence Tracker — Summary Dashboard
A2: Counts update automatically as you fill in the Evidence Tracker sheet
A4: Process Area | B4: Total Steps | C4: Exists | D4: Partial | E4: Missing | F4: % Complete
A5: Delivery Process | B5: 9 | C5: =COUNTIF('Evidence Tracker'!H5:H13,"Exists") | D5: =COUNTIF('Evidence Tracker'!H5:H13,"Partial") | E5: =COUNTIF('Evidence Tracker'!H5:H13,"Missing") | F5: =IFERROR((C5+D5/2)/9,0)
A6: Validation & QA | B6: 8 | C6: =COUNTIF('Evidence Tracker'!H14:H21,"Exists") | D6: =COUNTIF('Evidence Tracker'!H14:H21,"Partial") | E6: =COUNTIF('Evidence Tracker'!H14:H21,"Missing") | F6: =IFERROR((C6+D6/2)/8,0)
A7: Data Sourcing & Lineage | B7: 7 | C7: =COUNTIF('Evidence Tracker'!H22:H28,"Exists") | D7: =COUNTIF('Evidence Tracker'!H22:H28,"Partial") | E7: =COUNTIF('Evidence Tracker'!H22:H28,"Missing") | F7: =IFERROR((C7+D7/2)/7,0)
A8: Governance & Issue Mgmt | B8: 8 | C8: =COUNTIF('Evidence Tracker'!H29:H36,"Exists") | D8: =COUNTIF('Evidence Tracker'!H29:H36,"Partial") | E8: =COUNTIF('Evidence Tracker'!H29:H36,"Missing") | F8: =IFERROR((C8+D8/2)/8,0)
A9: Access Control & Security | B9: 5 | C9: =COUNTIF('Evidence Tracker'!H37:H41,"Exists") | D9: =COUNTIF('Evidence Tracker'!H37:H41,"Partial") | E9: =COUNTIF('Evidence Tracker'!H37:H41,"Missing") | F9: =IFERROR((C9+D9/2)/5,0)
A10: Change Management | B10: 6 | C10: =COUNTIF('Evidence Tracker'!H42:H47,"Exists") | D10: =COUNTIF('Evidence Tracker'!H42:H47,"Partial") | E10: =COUNTIF('Evidence Tracker'!H42:H47,"Missing") | F10: =IFERROR((C10+D10/2)/6,0)
A11: TOTAL | B11: =SUM(B5:B10) | C11: =SUM(C5:C10) | D11: =SUM(D5:D10) | E11: =SUM(E5:E10) | F11: =IFERROR(SUM(C5:C10)/(SUM(B5:B10)),0)
A13: KEY PROJECT STATS (FY2025)
A14: Total Work Packages | E14: 4
A15: Total Metric Definitions | E15: 86
A16: Total Assessable Units (AUs) | E16: 35
A17: Total Metric Instances | E17: 2,240
A18: Jira — BUILD COMPLETE | E18: 754
A19: Jira — BLOCKED (active) | E19: 49
A20: RAID Log Items | E20: 137
A21: Rahona Data Sources | E21: 20
A22: ADIDO Data Sources | E22: 73

Sheet Instructions
A1: HOW TO USE THIS EVIDENCE TRACKER
A2: PURPOSE | B2: This tracker maps every process step to its required evidence artifact. Use it to identify gaps, track progress, and demonstrate audit readiness.
A3: STATUS COLUMN (H) | B3: Select from: Exists / Partial / Missing / N/A • Exists = artifact is complete and located • Partial = artifact exists but is incomplete • Missing = artifact not yet produced • N/A = step not applicable to this cycle
A4: ARTIFACT NAME (F) | B4: Enter the actual filename of the evidence (e.g., 'Reconciliation_Report_WP01_Apr2026.xlsx')
A5: LOCATION (G) | B5: Paste the full SharePoint URL or Jira ticket ID where the evidence lives
A6: JIRA TICKETS (I) | B6: Enter comma-separated Jira ticket IDs that serve as evidence for this step (e.g., FY25DATA-359, FY25DATA-401)
A7: PRIORITY (M) | B7: High = must exist for audit / Medium = important but not blocking / Low = nice to have
A8: AUDIT READY (P) | B8: Yes = evidence is complete, located, and verified In Progress = being worked on No = not started
A9: SUMMARY DASHBOARD | B9: The Summary Dashboard sheet auto-calculates completion % by process area as you update the Status column.
A10: SHAREPOINT STRUCTURE | B10: 00 - Audit Navigation 01 - Delivery Process 02 - Validation & QA 03 - Data Sourcing & Lineage 04 - Governance & Issue Mgmt 05 - Access Control & Security 06 - Change Management 07 - Process Flow Diagrams 08 - Archive
A11: OWNER | B11: FCRM Enterprise Risk Assessment Reporting Team | April 2026 | Internal
