Workbook

Sheet Process Inventory
A1: FCRM Risk Assessment FY2025 — Process Inventory
A2: Complete process detail: inputs, actions, outputs, approvals, Jira states, tools, and SOP references | Internal | April 2026
A4: Process | B4: Sub-Process / Control Area | C4: Step # | D4: Step Name | E4: Owner | F4: Inputs | G4: Actions / Description | H4: Outputs / Deliverables | I4: Approval Required? | J4: Approver | K4: Jira Workflow State | L4: Tool / System | M4: SOP Reference | N4: Notes
A5: Delivery Process | B5: Requirement Definition; Data Acquisition; Logic Dev; Change Mgmt; Deployment; Delivery; BAU | C5: 0 | D5: Intake Request | E5: Amandeep | F5: Business requirements, CDE list, AU scope | G5: Raise intake request with purpose, AUs in scope, expected output and timelines. Identify Critical Data Elements (ERA/FCRM/Business). Perform initial review (1a/1b/Bas). IR review and challenge with core business. | H5: Jira intake ticket, CDE list, initial review record | I5: Yes | J5: Team Lead / Business | K5: BUSINESS LOGIC DESIGN DEF | L5: Jira | M5: Delivery Process SOP v1.2
C6: 1 | D6: Scope / Requirement Definition | E6: Amandeep | F6: Intake ticket, SOW, AU list | G6: Identify and capture Critical Data Elements required to close RA cycle for FY2025. Define scope boundaries. Business logic and queries approved by First Line. | H6: Scope & Requirements Document, SOW reference | I6: Yes | J6: AVP+ | K6: BUSINESS LOGIC DESIGN DEF | L6: SharePoint | M6: Delivery Process SOP v1.2
C7: 2 | D7: Data Acquisition | E7: Amandeep | F7: Approved scope, Rahona/ADIDO access, PIA approvals | G7: Source data from Rahona (20 sources) and ADIDO (73 sources). Load to Canada Analytical Zone (CA AZ). Validate data integrity and completeness post-extraction. | H7: Extracted dataset files (.csv/.parquet) in CA AZ, extraction scripts, extraction validation report | I7: No | K7: DATA SOURCE(S) IDENTIFIED → DATA PROVISIONED IN AZ | L7: Rahona / ADIDO / CA AZ | M7: Delivery Process SOP v1.2
C8: 3 | D8: Logic Development (Build) | E8: Karthik | F8: Extracted datasets in CA AZ, metric definitions, business logic approved by 1LOD | G8: Write Python-SQL queries, joins, filters, aggregations. Define and generate output. Document logic and transformations. | H8: Python-SQL code in Git, Jira ticket in BUILD IN PROGRESS, transformation logic documentation | I8: No | K8: BUILD IN PROGRESS (PART) → BUILD IN PROGRESS (FULL) | L8: GitHub / CA AZ | M8: Delivery Process SOP v1.2
C9: 4 | D9: Technical Specifications (Build) | E9: Karthik | F9: Build code, metric definitions, lineage requirements | G9: Document technical specifications including transformation logic, field-level mapping, data lineage from source to output. | H9: Tech spec document, source-to-report mapping, field-level lineage | I9: No | K9: BUILD IN PROGRESS (FULL) | L9: SharePoint / GitHub | M9: Delivery Process SOP v1.2
C10: 5 | D10: Output Validation | E10: Karthik | F10: Build outputs, expected metric values, validation criteria | G10: Validate output against expected results. Cross-check with source data. Verify format and structure meet regulatory requirements. | H10: Output validation report, reconciliation results | I10: No | K10: BUILD COMPLETE | L10: SharePoint | M10: QA & Governance SOP v2.1
C11: 6 | D11: Approval | E11: Karthik | F11: Validated outputs, completed validation checklist | G11: Obtain PO Concurrence. Transition Jira to PO APPROVED. Reviewers must be independent of preparer. Approver must be AVP or higher. | H11: Jira ticket in PO APPROVED state, approval record | I11: Yes | J11: AVP+ | K11: PO CONCURRENCE → PO APPROVED | L11: Jira | M11: Approvals Document v1.1
C12: 7 | D12: Deployment | E12: Karthik | F12: Approved outputs, deployment checklist | G12: Deploy metric outputs to production. Record deployment details. Confirm successful release. | H12: Deployment log, release record | I12: Yes | J12: Team Lead | K12: PO APPROVED | L12: Jira / SharePoint | M12: Delivery Process SOP v1.2
C13: 8 | D13: Delivery / Document Output | E13: Karthik | F13: Deployed outputs | G13: Deliver final metric outputs. Document results. Store in SharePoint. Confirm delivery with stakeholders. | H13: Final output files, delivery confirmation, output documentation | I13: No | K13: PO APPROVED | L13: SharePoint / CA AZ | M13: Delivery Process SOP v1.2
A14: Validation & Quality Assurance | B14: DQ Checks; Reconciliation; Peer Review; Output Verification | C14: 1 | D14: Validation Planning | E14: Priyanshi | F14: Scope document, metric definitions, AU list | G14: Define validation scope (datasets, systems, outputs). Identify key controls and risk areas. Establish timelines and milestones. Assign roles and responsibilities. Document methodology and acceptance criteria. | H14: Validation Plan Document, Risk Assessment Matrix | I14: No | K14: BUSINESS LOGIC DESIGN DEF | L14: SharePoint | M14: QA & Governance SOP v2.1
C15: 2 | D15: Data Quality Checks | E15: Priyanshi | F15: Extracted datasets in CA AZ | G15: Completeness: no missing/null critical fields. Accuracy: validate against source systems (95% threshold). Consistency: cross-check values. Uniqueness: identify duplicates. Timeliness: data up-to-date. Methods: automated scripts + manual sampling. | H15: DQ check results, profiling reports, issue log | I15: No | K15: DATA PROVISIONED IN AZ | L15: CA AZ / SharePoint | M15: QA & Governance SOP v2.1
C16: 3 | D16: Reconciliation | E16: Priyanshi | F16: Source data counts, processed data counts | G16: Reconcile record counts between source and processed data. Validate key financial metrics. Identify and investigate variances. Document all reconciliation results. | H16: Reconciliation reports, variance analysis logs | I16: No | K16: DATA PROVISIONED IN AZ | L16: SharePoint | M16: QA & Governance SOP v2.1
C17: 4 | D17: Reasonability Analysis | E17: Priyanshi | F17: Metric outputs, historical data, expected thresholds | G17: Assess whether AML outputs are logical and within expected thresholds. Trend analysis. Comparison with historical data. Outlier detection. Threshold validation. Check for sudden spikes/drops. | H17: Trend analysis output, outlier detection log, threshold validation report | I17: No | K17: BUILD IN PROGRESS (FULL) | L17: SharePoint | M17: QA & Governance SOP v2.1
C18: 5 | D18: Peer Review | E18: Sujai | F18: Build outputs, methodology documentation | G18: Assign reviewer independent of preparer. Review methodology, calculations, and outputs. Validate assumptions and logic. Document review comments and resolutions. Privacy compliance check (PIA BUILD → WITH PRIVACY TEAM → PIA APPROVED). | H18: Peer review sign-off, review comments log, AU REVIEW APPROVAL Jira state | I18: Yes | J18: Independent reviewer (not preparer) | K18: AU REVIEW APPROVAL | L18: SharePoint / Jira | M18: QA & Governance SOP v2.1
C19: 6 | D19: Output Verification | E19: Sujai | F19: Final metric outputs, format requirements | G19: Verify output format and structure. Validate key fields and calculations. Cross-check with source and intermediate data. Ensure regulatory compliance. Execution gating: cannot proceed until Steps 1–5 cleared. | H19: Output verification report, format compliance log | I19: No | K19: BUILD COMPLETE | L19: SharePoint | M19: Output Validation Document v1.1
C20: 7 | D20: Issue Logging | E20: Sujai | F20: Identified issues from any prior step | G20: Log issues in RAID log immediately. Transition Jira to BLOCKED state. Categorize severity (P1=critical data gap, P2=systemic failure). Assign ownership and due dates. Track resolution status. Maintain audit trail. | H20: RAID log entry, Jira BLOCKED ticket with full issue detail | I20: No | K20: BLOCKED | L20: Jira / SharePoint | M20: QA & Governance SOP v2.1
C21: 8 | D21: Sign-Off & Approval | E21: Sujai | F21: Completed validation checklist, all issues resolved or accepted | G21: Ensure all validation steps are completed. Confirm all issues resolved or formally risk-accepted. Obtain approvals (AVP+). Reviewer cannot be same as preparer. Transition Jira to PO CONCURRENCE → PO APPROVED. | H21: Signed approval record, final validation report | I21: Yes | J21: AVP+ | K21: PO CONCURRENCE → PO APPROVED | L21: SharePoint / Jira | M21: Approvals Document v1.1
A22: Data Sourcing & Lineage | B22: Source Identification; Access; Extraction; Lineage; Retention | C22: 1 | D22: Source Identification | E22: Hua | F22: Business requirements, metric definitions, SOW | G22: Review business and regulatory requirements. Create Master_Data_source_FY2025.xlsx to identify all relevant data sources per metric. Collaborate with business stakeholders. Document system names, tables, owners, data attributes. | H22: Master_Data_source_FY2025.xlsx, source identification log | I22: No | K22: BUSINESS LOGIC DESIGN DEF | L22: SharePoint | M22: Data Sourcing & Lineage v1.0
C23: 2 | D23: Access Enablement | E23: Hua | F23: Identified data sources, organizational PIA guidelines | G23: Initiate Privacy Impact Assessment (PIA) process for each data source. Submit access requests. Track and follow up on access approvals. Maintain records of all access permissions and compliance checks. | H23: PIA approval records, access request forms, access approval log | I23: Yes | J23: Privacy Team / Data Owner | K23: DATA SOURCE(S) IDENTIFIED | L23: SharePoint | M23: Data Sourcing & Lineage v1.0
C24: 3 | D24: Data Extraction | E24: Hua | F24: Approved access credentials, Master Data Source Sheet | G24: Use approved credentials to connect to Rahona (20 sources) and ADIDO (73 sources). Extract relevant data fields per requirements. Store in CA AZ. Validate integrity and completeness post-extraction. | H24: Extracted dataset files (.csv/.parquet), extraction scripts, extraction validation report | I24: No | K24: DATA PROVISIONED IN AZ | L24: Rahona / ADIDO / CA AZ | M24: Data Sourcing & Lineage v1.0
C25: 4 | D25: Data Understanding | E25: Subham | F25: Extracted datasets in CA AZ | G25: Create database views or data models. Profile datasets for completeness, accuracy, consistency. Document data definitions, data types, key attributes. Identify and address data quality issues. | H25: Data profiling reports, data dictionary / metadata documentation, data quality assessment report | I25: No | K25: DATA PROVISIONED IN AZ | L25: CA AZ / SharePoint | M25: Data Sourcing & Lineage v1.0
C26: 5 | D26: Lineage Documentation | E26: Subham | F26: Extraction scripts, transformation logic, metric definitions | G26: Build queries producing result values for each metric. Map complete data journey from extraction to reporting including all transformations and business logic applied. Maintain lineage diagrams. Ensure accessible for audit. | H26: Data lineage diagrams, transformation logic documentation, lineage register | I26: No | K26: BUILD IN PROGRESS (FULL) | L26: SharePoint / GitHub | M26: Data Sourcing & Lineage v1.0
C27: 6 | D27: Refresh Management | E27: Raghul | F27: CA AZ datasets, business/audit refresh requests | G27: Data pulled for RA FY2025 and refreshed at source system level on-demand (not fixed schedule). RA team extracts and stores in CA AZ. Document all refresh activities. Validate data integrity after each refresh. | H27: Refresh activity log, extracted dataset files (refreshed), refresh validation reports | I27: No | K27: DATA PROVISIONED IN AZ | L27: CA AZ / SharePoint | M27: Data Sourcing & Lineage v1.0
C28: 7 | D28: Data Retention | E28: Raghul | F28: CA AZ datasets, organizational retention policies | G28: Currently no defined retention policy — datasets stored in CA AZ without a defined retention period. Periodically review organizational and regulatory requirements. Update documentation if requirements change. | H28: Data retention statement, retention policy reference (if applicable), retention/disposal log | I28: No | K28: N/A | L28: SharePoint | M28: Data Sourcing & Lineage v1.0
A29: Governance & Issue Management | B29: Decision Logging; Assumptions; Issue Mgmt; Escalation; Risk Acceptance | C29: 1 | D29: Decision Logging | E29: Patty | F29: Business logic discussions, methodology decisions | G29: All business logic, scoping, and methodological decisions must be captured in Jira. Unlogged out-of-band decisions are not permitted. Initial business rules and metric definitions formalized while ticket is in BUSINESS LOGIC DESIGN DEF and BUSINESS LOGIC SEMANTIC states. | H29: Jira ticket in BUSINESS LOGIC DESIGN DEF state with full decision notes | I29: No | K29: BUSINESS LOGIC DESIGN DEF / BUSINESS LOGIC SEMANTIC | L29: Jira | M29: QA & Governance SOP v2.1
C30: 2 | D30: Assumption Tracking | E30: Patty | F30: Ambiguous requirements, proxy data, default thresholds | G30: Ambiguities in requirements, default thresholds, or proxy data assumptions must be formally documented. Resolved while ticket is in METRIC DEFINITION CLARIFICATION or BAU CDE DOCUMENTATION state. | H30: Jira ticket in METRIC DEFINITION CLARIFICATION state, assumption log | I30: No | K30: METRIC DEFINITION CLARIFICATION / BAU CDE DOCUMENTATION | L30: Jira | M30: QA & Governance SOP v2.1
C31: 3 | D31: Issue Logging | E31: Patty | F31: Identified blockers, data issues, QA failures | G31: If metric cannot proceed due to upstream QA failure or missing source file, Jira ticket must immediately transition to BLOCKED. Corresponding entry captured in formal RAID Log. | H31: RAID log entry, Jira BLOCKED ticket with issue detail | I31: No | K31: BLOCKED | L31: Jira / SharePoint | M31: QA & Governance SOP v2.1
C32: 4 | D32: Severity Assessment | E32: Patty | F32: Logged issues in RAID | G32: Issues undergo standardized severity assessment: P1 = critical data gaps, P2 = systemic failures, P3 = localized logic discrepancies. Priority determines escalation urgency and SLA. | H32: Severity classification (P1/P2/P3) in RAID log | I32: No | K32: BLOCKED | L32: Jira / SharePoint | M32: QA & Governance SOP v2.1
C33: 5 | D33: Escalation Pathways | E33: Tom | F33: Unresolved BLOCKED issues beyond SLA | G33: When issue cannot be resolved within SLAs, use structured escalation matrix: Developer → Team Lead → Project Manager → Business Stakeholders / 2LOD. Escalations must clearly categorize blocker type. | H33: Escalation record, Jira comments showing escalation chain, 2LOD notification | I33: No | K33: BLOCKED | L33: Jira / Email | M33: QA & Governance SOP v2.1
C34: 6 | D34: Resolution & Unblocking | E34: Tom | F34: Resolved issues, RAID log closure | G34: Issue is formally considered resolved only when marked 'Closed' in RAID log. Only then may the Jira ticket leave BLOCKED state and proceed toward READY FOR FINAL REVIEW. | H34: RAID log closure record, Jira state transition off BLOCKED | I34: Yes | J34: Team Lead | K34: BLOCKED → READY FOR FINAL REVIEW | L34: Jira / SharePoint | M34: QA & Governance SOP v2.1
C35: 7 | D35: Risk Acceptance | E35: Tom | F35: Unresolvable issues, data below 95% threshold | G35: If data completeness falls below required thresholds and cannot be remediated before reporting deadlines, must be formally risk-accepted by all key stakeholders. Metric ticket transitioned to NOT AVAILABLE. Triggers default to higher risk rating for impacted AU. | H35: Risk acceptance record, metric in NOT AVAILABLE Jira state, stakeholder sign-off | I35: Yes | J35: AVP+ / 2LOD | K35: NOT AVAILABLE | L35: SharePoint / Jira | M35: QA & Governance SOP v2.1
C36: 8 | D36: Decommissioning | E36: Tom | F36: Out-of-scope metrics, retired AUs, deprecated work packages | G36: Metrics, AUs, or Work Packages retired or no longer applicable must be transitioned to NO LONGER REQUIRED or NOT APPLICABLE Jira states. Ensures historical traceability. | H36: Jira state: NO LONGER REQUIRED or NOT APPLICABLE, SOW scope change log entry | I36: No | K36: NO LONGER REQUIRED / NOT APPLICABLE | L36: Jira / SharePoint | M36: QA & Governance SOP v2.1
A37: Access Control & Security | B37: PIAs; Access Control; DEV vs PROD; Periodic Reviews; Retention | C37: 1 | D37: PIA Initiation | E37: Hua | F37: Data source list, privacy requirements | G37: Initiate Privacy Impact Assessment for each data source requiring access to personal or sensitive data. Follow organizational PIA guidelines. Coordinate with Privacy Team. PIA BUILD → WITH PRIVACY TEAM → PIA APPROVED. | H37: PIA documentation, PIA Jira state transitions | I37: Yes | J37: Privacy Team | K37: PIA BUILD → WITH PRIVACY TEAM → PIA APPROVED | L37: SharePoint / Jira | M37: Access Control SOP
C38: 2 | D38: Access Request & Approval | E38: Hua | F38: Approved PIA, system access requirements | G38: Submit access requests for all required systems and datasets. Track and follow up on approvals. Maintain records of all access permissions and compliance checks for audit purposes. | H38: Access request forms, access approval records, access approval log | I38: Yes | J38: Data Owner / IT Security | K38: DATA SOURCE(S) IDENTIFIED | L38: SharePoint | M38: Access Control SOP
C39: 3 | D39: Access Control Matrix | E39: TBD | F39: Approved access records | G39: Maintain access control matrix documenting who has access to which systems, datasets, and environments. Document segregation of duties. | H39: Access control matrix, segregation of duties documentation | I39: No | K39: N/A | L39: SharePoint | M39: Access Control SOP
C40: 4 | D40: DEV vs PROD Separation | E40: TBD | F40: Environment configuration | G40: Maintain strict separation between DEV and PROD environments. No production data in DEV without approval. Document environment boundaries and access controls. | H40: DEV/PROD separation evidence, environment access records | I40: No | K40: N/A | L40: SharePoint | M40: Access Control SOP
C41: 5 | D41: Periodic Access Review | E41: TBD | F41: Current access records | G41: Conduct periodic reviews of all access permissions. Remove stale or unnecessary access. Document review outcomes and maintain audit trail of access changes. | H41: Periodic access review log, attestation records | I41: Yes | J41: Team Lead / Security | K41: N/A | L41: SharePoint | M41: Access Control SOP
...

Sheet Evidence Tracker
A1: FCRM Risk Assessment FY2025 — Evidence Tracker
A2: Maps each process step to required evidence, artifact locations, status, and audit readiness | Internal | April 2026
A4: Process | B4: Step # | C4: Step Name | D4: Owner | E4: Expected Evidence / Artifact | F4: Artifact Name / File | G4: SharePoint / Jira Location | H4: Status | I4: Jira Ticket(s) | J4: Last Verified | K4: Verified By | L4: Gap / Notes | M4: Priority | N4: Due Date | O4: SOP Reference | P4: Audit Ready?
A5: Delivery Process | B5: 0 | C5: Intake Request | D5: Amandeep | E5: Jira ticket, CDE documentation | H5: Missing | O5: Delivery Process SOP v1.2 | P5: No
B6: 1 | C6: Scope / Requirement Definition | D6: Amandeep | E6: Scope & Requirements Document v1.2 | H6: Missing | O6: Delivery Process SOP v1.2 | P6: No
B7: 2 | C7: Data Acquisition | D7: Amandeep | E7: Extracted files, extraction scripts | H7: Missing | O7: Delivery Process SOP v1.2 | P7: No
B8: 3 | C8: Logic Development (Build) | D8: Karthik | E8: Git commit history, code files | H8: Missing | O8: Delivery Process SOP v1.2 | P8: No
B9: 4 | C9: Technical Specifications (Build) | D9: Karthik | E9: Technical specification document | H9: Missing | O9: Delivery Process SOP v1.2 | P9: No
B10: 5 | C10: Output Validation | D10: Karthik | E10: Output validation report | H10: Missing | O10: QA & Governance SOP v2.1 | P10: No
B11: 6 | C11: Approval | D11: Karthik | E11: Jira state transition, approval record | H11: Missing | O11: Approvals Document v1.1 | P11: No
B12: 7 | C12: Deployment | D12: Karthik | E12: Deployment log | H12: Missing | O12: Delivery Process SOP v1.2 | P12: No
B13: 8 | C13: Delivery / Document Output | D13: Karthik | E13: Output files, delivery confirmation | H13: Missing | O13: Delivery Process SOP v1.2 | P13: No
A14: Validation & Quality Assurance | B14: 1 | C14: Validation Planning | D14: Priyanshi | E14: Validation Plan Document | H14: Missing | O14: QA & Governance SOP v2.1 | P14: No
B15: 2 | C15: Data Quality Checks | D15: Priyanshi | E15: DQ check output files, profiling reports | H15: Missing | O15: QA & Governance SOP v2.1 | P15: No
B16: 3 | C16: Reconciliation | D16: Priyanshi | E16: Reconciliation reports, variance logs | H16: Missing | O16: QA & Governance SOP v2.1 | P16: No
B17: 4 | C17: Reasonability Analysis | D17: Priyanshi | E17: Reasonability analysis report | H17: Missing | O17: QA & Governance SOP v2.1 | P17: No
B18: 5 | C18: Peer Review | D18: Sujai | E18: Peer review sign-off document | H18: Missing | O18: QA & Governance SOP v2.1 | P18: No
B19: 6 | C19: Output Verification | D19: Sujai | E19: Output verification report | H19: Missing | O19: Output Validation Document v1.1 | P19: No
B20: 7 | C20: Issue Logging | D20: Sujai | E20: RAID log, Jira BLOCKED ticket | H20: Missing | O20: QA & Governance SOP v2.1 | P20: No
B21: 8 | C21: Sign-Off & Approval | D21: Sujai | E21: Signed approval record | H21: Missing | O21: Approvals Document v1.1 | P21: No
A22: Data Sourcing & Lineage | B22: 1 | C22: Source Identification | D22: Hua | E22: Master Data Source Sheet | H22: Missing | O22: Data Sourcing & Lineage v1.0 | P22: No
B23: 2 | C23: Access Enablement | D23: Hua | E23: PIA records, access approval log | H23: Missing | O23: Data Sourcing & Lineage v1.0 | P23: No
B24: 3 | C24: Data Extraction | D24: Hua | E24: Extracted files, extraction scripts | H24: Missing | O24: Data Sourcing & Lineage v1.0 | P24: No
B25: 4 | C25: Data Understanding | D25: Subham | E25: Data profiling reports, data dictionary | H25: Missing | O25: Data Sourcing & Lineage v1.0 | P25: No
B26: 5 | C26: Lineage Documentation | D26: Subham | E26: Lineage diagrams, transformation logic doc | H26: Missing | O26: Data Sourcing & Lineage v1.0 | P26: No
B27: 6 | C27: Refresh Management | D27: Raghul | E27: Refresh activity log, refresh validation report | H27: Missing | O27: Data Sourcing & Lineage v1.0 | P27: No
B28: 7 | C28: Data Retention | D28: Raghul | E28: Data retention statement | H28: Missing | O28: Data Sourcing & Lineage v1.0 | P28: No
A29: Governance & Issue Management | B29: 1 | C29: Decision Logging | D29: Patty | E29: Jira decision tickets | H29: Missing | O29: QA & Governance SOP v2.1 | P29: No
B30: 2 | C30: Assumption Tracking | D30: Patty | E30: Jira assumption tickets | H30: Missing | O30: QA & Governance SOP v2.1 | P30: No
B31: 3 | C31: Issue Logging | D31: Patty | E31: RAID log, Jira BLOCKED ticket | H31: Missing | O31: QA & Governance SOP v2.1 | P31: No
B32: 4 | C32: Severity Assessment | D32: Patty | E32: RAID log with severity classification | H32: Missing | O32: QA & Governance SOP v2.1 | P32: No
B33: 5 | C33: Escalation Pathways | D33: Tom | E33: Jira escalation comments, email records | H33: Missing | O33: QA & Governance SOP v2.1 | P33: No
B34: 6 | C34: Resolution & Unblocking | D34: Tom | E34: RAID log closure, Jira state history | H34: Missing | O34: QA & Governance SOP v2.1 | P34: No
B35: 7 | C35: Risk Acceptance | D35: Tom | E35: Risk acceptance document, Jira state | H35: Missing | O35: QA & Governance SOP v2.1 | P35: No
B36: 8 | C36: Decommissioning | D36: Tom | E36: Jira state transition, SOW change log | H36: Missing | O36: QA & Governance SOP v2.1 | P36: No
A37: Access Control & Security | B37: 1 | C37: PIA Initiation | D37: Hua | E37: PIA documentation | H37: Missing | O37: Access Control SOP | P37: No
B38: 2 | C38: Access Request & Approval | D38: Hua | E38: Access request forms, approval records | H38: Missing | O38: Access Control SOP | P38: No
B39: 3 | C39: Access Control Matrix | D39: TBD | E39: Access control matrix | H39: Missing | O39: Access Control SOP | P39: No
B40: 4 | C40: DEV vs PROD Separation | D40: TBD | E40: Environment separation documentation | H40: Missing | O40: Access Control SOP | P40: No
B41: 5 | C41: Periodic Access Review | D41: TBD | E41: Access review log | H41: Missing | O41: Access Control SOP | P41: No
...

Sheet Summary Dashboard
A1: Evidence Tracker — Summary Dashboard
A2: Auto-updates as you fill in Status column in the Evidence Tracker sheet
A4: Process Area | B4: Total Steps | C4: Exists | D4: Partial | E4: Missing | F4: % Complete
A5: Delivery Process | B5: 9 | C5: =COUNTIF('Evidence Tracker'!H5:H13,"Exists") | D5: =COUNTIF('Evidence Tracker'!H5:H13,"Partial") | E5: =COUNTIF('Evidence Tracker'!H5:H13,"Missing") | F5: =IFERROR((C5+D5/2)/9,0)
A6: Validation & Quality Assurance | B6: 8 | C6: =COUNTIF('Evidence Tracker'!H14:H21,"Exists") | D6: =COUNTIF('Evidence Tracker'!H14:H21,"Partial") | E6: =COUNTIF('Evidence Tracker'!H14:H21,"Missing") | F6: =IFERROR((C6+D6/2)/8,0)
A7: Data Sourcing & Lineage | B7: 7 | C7: =COUNTIF('Evidence Tracker'!H22:H28,"Exists") | D7: =COUNTIF('Evidence Tracker'!H22:H28,"Partial") | E7: =COUNTIF('Evidence Tracker'!H22:H28,"Missing") | F7: =IFERROR((C7+D7/2)/7,0)
A8: Governance & Issue Management | B8: 8 | C8: =COUNTIF('Evidence Tracker'!H29:H36,"Exists") | D8: =COUNTIF('Evidence Tracker'!H29:H36,"Partial") | E8: =COUNTIF('Evidence Tracker'!H29:H36,"Missing") | F8: =IFERROR((C8+D8/2)/8,0)
A9: Access Control & Security | B9: 5 | C9: =COUNTIF('Evidence Tracker'!H37:H41,"Exists") | D9: =COUNTIF('Evidence Tracker'!H37:H41,"Partial") | E9: =COUNTIF('Evidence Tracker'!H37:H41,"Missing") | F9: =IFERROR((C9+D9/2)/5,0)
A10: Change Management | B10: 6 | C10: =COUNTIF('Evidence Tracker'!H42:H47,"Exists") | D10: =COUNTIF('Evidence Tracker'!H42:H47,"Partial") | E10: =COUNTIF('Evidence Tracker'!H42:H47,"Missing") | F10: =IFERROR((C10+D10/2)/6,0)
A11: TOTAL | B11: =SUM(B5:B10) | C11: =SUM(C5:C10) | D11: =SUM(D5:D10) | E11: =SUM(E5:E10) | F11: =IFERROR(SUM(C5:C10)/SUM(B5:B10),0)
A13: KEY PROJECT STATS (FY2025)
A14: Total Work Packages | E14: 4
A15: Total Metric Definitions | E15: 86
A16: Total Assessable Units (AUs) | E16: 35
A17: Total Metric Instances | E17: 2,240
A18: Jira — BUILD COMPLETE | E18: 754
A19: Jira — BLOCKED (active) | E19: 49
A20: RAID Log Items | E20: 137
A21: Rahona Data Sources | E21: 20
A22: ADIDO Data Sources | E22: 73

Sheet Resourcing Team
A1: FY2025 Risk Assessment — Resourcing & Process Ownership
A2: Maps team members to process ownership and step assignments
A4: Process | B4: Sub-Process / Control Area | C4: Process Steps | D4: Resources | E4: Notes
A5: Delivery Process | B5: Requirement Definition; Data Acquisition; Logic Dev; Change Mgmt; Deployment; Delivery; BAU | C5: 0. Intake Request 1. Scope / Requirement Definition 2. Data Acquisition 3. Logic Development (Build) 4. Technical Specifications (Build) 5. Output Validation 6. Approval 7. Deployment 8. Output / Document | D5: Amandeep: Steps 0–4 Karthik: Steps 5–8
A6: Validation & Quality Assurance | B6: DQ Checks; Reconciliation; Peer Review; Output Verification | C6: 1. Validation Planning 2. Data Quality Checks 3. Reconciliation 4. Reasonability Analysis 5. Peer Review 6. Output Verification 7. Issue Logging 8. Sign-Off & Approval | D6: Priyanshi: Steps 1–4 Sujai: Steps 5–8
A7: Data Sourcing & Lineage | B7: Source Identification; Access; Extraction; Lineage; Retention | C7: 1. Source Identification 2. Access Enablement 3. Data Extraction 4. Data Understanding 5. Lineage Documentation 6. Refresh Management 7. Data Retention | D7: Hua: Steps 1–3 Subham: Steps 4–5 Raghul: Steps 6–7
A8: Governance & Issue Management | B8: Decision Logging; Assumptions; Issue Mgmt; Escalation; Risk Acceptance | C8: 1. Decision Logging 2. Assumption Tracking 3. Issue Logging 4. Severity Assessment 5. Escalation Pathways 6. Resolution & Unblocking 7. Risk Acceptance 8. Decommissioning | D8: Patty: Steps 1–4 Tom: Steps 5–8
A9: Access Control & Security | B9: PIAs; Access Control Matrix; DEV vs PROD; Periodic Reviews | C9: 1. PIA Initiation 2. Access Request & Approval 3. Access Control Matrix 4. DEV vs PROD Separation 5. Periodic Access Review | D9: Hua: Steps 1–2 TBD: Steps 3–5 | E9: ⚠ Owners TBD — confirm with team leads
A10: Change Management | B10: Change Tickets; Git Version Control; Approvals; Deployment; Rollback | C10: 1. Change Request 2. Impact Assessment 3. Change Approval 4. Version Control 5. Deployment & Rollback 6. Scope Change Logging | D10: TBD: Steps 1–5 Richard Ng: Step 6 | E10: ⚠ Owners TBD — confirm with team leads
